Workbook

Sheet data
A1: BOJ Swap Distortion – データ入力シート（黄色セル = LSEG RTDフィード）
A2: ⚠ 現在はダミーデータです。LSEGのRTD / Add-in でValue列を自動更新してください。
A4: トレード日 | B4: 46103
A5: スポット日（T+2BD） | B5: 46107 | C5: ※ 実際はT+2BD、土日祝考慮。手動更新
A7: ■ BOJスワップ フォワード金利（JPBOJ1-8ONI=TRDT）
A8: LSEGティッカー | B8: フォワード金利（%） | C8: MPM実効日（ダミー） | D8: 累積日数 Spot→MPM_i | E8: 備考（MPM会合日）
A9: JPBOJ1ONI=TRDT | B9: 0.00495 | C9: 46141 | D9: =C9-$B$5 | E9: 会合1: 2026/04/28 → 実効日:2026/04/29
A10: JPBOJ2ONI=TRDT | B10: 0.005 | C10: 46190 | D10: =C10-$B$5 | E10: 会合2: 2026/06/16 → 実効日:2026/06/17
A11: JPBOJ3ONI=TRDT | B11: 0.0051 | C11: 46235 | D11: =C11-$B$5 | E11: 会合3: 2026/07/31 → 実効日:2026/08/01
A12: JPBOJ4ONI=TRDT | B12: 0.0053 | C12: 46284 | D12: =C12-$B$5 | E12: 会合4: 2026/09/18 → 実効日:2026/09/19
A13: JPBOJ5ONI=TRDT | B13: 0.00535 | C13: 46326 | D13: =C13-$B$5 | E13: 会合5: 2026/10/30 → 実効日:2026/10/31
A14: JPBOJ6ONI=TRDT | B14: 0.0057 | C14: 46375 | D14: =C14-$B$5 | E14: 会合6: 2026/12/18 → 実効日:2026/12/19
A15: JPBOJ7ONI=TRDT | B15: 0.0059 | C15: 46416 | D15: =C15-$B$5 | E15: 会合7: 2027/01/28 → 実効日:2027/01/29
A16: JPBOJ8ONI=TRDT | B16: 0.0062 | C16: 46465 | D16: =C16-$B$5 | E16: 会合8: 2027/03/18 → 実効日:2027/03/19
A18: ■ スポット金利 直接クォート（JPYOIS1-12M, 15M = ICAP）
A19: LSEGティッカー | B19: スポット金利（%） | C19: 実日数（ACT/MF） | D19: テナー | E19: 備考
A20: JPYOIS1M=ICAP | B20: 0.00485 | C20: 31 | D20: 1M | E20: ← LSEGより（MF適用後の実日数）
A21: JPYOIS2M=ICAP | B21: 0.0049 | C21: 62 | D21: 2M | E21: ← LSEGより（MF適用後の実日数）
A22: JPYOIS3M=ICAP | B22: 0.00498 | C22: 91 | D22: 3M | E22: ← LSEGより（MF適用後の実日数）
A23: JPYOIS4M=ICAP | B23: 0.0051 | C23: 122 | D23: 4M | E23: ← LSEGより（MF適用後の実日数）
A24: JPYOIS5M=ICAP | B24: 0.0052 | C24: 153 | D24: 5M | E24: ← LSEGより（MF適用後の実日数）
A25: JPYOIS6M=ICAP | B25: 0.00535 | C25: 184 | D25: 6M | E25: ← LSEGより（MF適用後の実日数）
A26: JPYOIS7M=ICAP | B26: 0.00548 | C26: 214 | D26: 7M | E26: ← LSEGより（MF適用後の実日数）
A27: JPYOIS8M=ICAP | B27: 0.00558 | C27: 245 | D27: 8M | E27: ← LSEGより（MF適用後の実日数）
A28: JPYOIS9M=ICAP | B28: 0.00565 | C28: 275 | D28: 9M | E28: ← LSEGより（MF適用後の実日数）
A29: JPYOIS10M=ICAP | B29: 0.0057 | C29: 306 | D29: 10M | E29: ← LSEGより（MF適用後の実日数）
A30: JPYOIS11M=ICAP | B30: 0.00575 | C30: 337 | D30: 11M | E30: ← LSEGより（MF適用後の実日数）
A31: JPY1YOIS=ICAP | B31: 0.0058 | C31: 368 | D31: 12M | E31: ← LSEGより（MF適用後の実日数）
A32: JPYOIS15M=ICAP | B32: 0.00595 | C32: 459 | D32: 15M | E32: ← LSEGより（MF適用後の実日数）

Sheet analysis
A1: BOJスワップ → インプライドスポット金利 逆算・歪み分析
A3: トレード日 | B3: =data!B4
A4: スポット日 | B4: =data!B5
A6: 【Step 1】 ブートストラップ: BOJフォワード金利 → 累積FV（割引係数の逆数）
A7: テナー | B7: MPM実効日 | C7: 累積日数 D_i | D7: 期間日数 ΔD_i | E7: フォワードM_i (小数) | F7: 累積FV_i =1/DF_i | G7: 割引係数 DF_i | H7: ゼロレート検証 (FV_i-1)×365/D_i
A8: M1 | B8: =data!C9 | C8: =data!D9 | D8: =C8 | E8: =data!B9 | F8: =1+E8*D8/365 | G8: =1/F8 | H8: =(F8-1)*365/C8
A9: M2 | B9: =data!C10 | C9: =data!D10 | D9: =C9-C8 | E9: =data!B10 | F9: =F8*(1+E9*D9/365) | G9: =1/F9 | H9: =(F9-1)*365/C9
A10: M3 | B10: =data!C11 | C10: =data!D11 | D10: =C10-C9 | E10: =data!B11 | F10: =F9*(1+E10*D10/365) | G10: =1/F10 | H10: =(F10-1)*365/C10
A11: M4 | B11: =data!C12 | C11: =data!D12 | D11: =C11-C10 | E11: =data!B12 | F11: =F10*(1+E11*D11/365) | G11: =1/F11 | H11: =(F11-1)*365/C11
A12: M5 | B12: =data!C13 | C12: =data!D13 | D12: =C12-C11 | E12: =data!B13 | F12: =F11*(1+E12*D12/365) | G12: =1/F12 | H12: =(F12-1)*365/C12
A13: M6 | B13: =data!C14 | C13: =data!D14 | D13: =C13-C12 | E13: =data!B14 | F13: =F12*(1+E13*D13/365) | G13: =1/F13 | H13: =(F13-1)*365/C13
A14: M7 | B14: =data!C15 | C14: =data!D15 | D14: =C14-C13 | E14: =data!B15 | F14: =F13*(1+E14*D14/365) | G14: =1/F14 | H14: =(F14-1)*365/C14
A15: M8 | B15: =data!C16 | C15: =data!D16 | D15: =C15-C14 | E15: =data!B16 | F15: =F14*(1+E15*D15/365) | G15: =1/F15 | H15: =(F15-1)*365/C15
A17: 【Step 2】 インプライドスポット金利の逆算 & 歪み計算
A18: テナー | B18: 実日数 D_T | C18: 実スポット 金利 | D18: FV(D_T) 逆算値 | E18: インプライド スポット金利 | F18: 歪み 実際－インプライド | G18: 歪み (bps) | H18: 備考 | J18: テナー | K18: インプライドスポット(%) | L18: 実スポット(%) | M18: 歪み(bps)
A19: 1M | B19: =data!C20 | C19: =data!B20 | D19: =IF(B19<=$C$8,(1+$E$8*B19/365),IF(B19<=$C$9,$F$8*(1+$E$9*(B19-$C$8)/365),IF(B19<=$C$10,$F$9*(1+$E$10*(B19-$C$9)/365),IF(B19<=$C$11,$F$10*(1+$E$11*(B19-$C$10)/365),IF(B19<=$C$12,$F$11*(1+$E$12*(B19-$C$11)/365),IF(B19<=$C$13,$F$12*(1+$E$13*(B19-$C$12)/365),IF(B19<=$C$14,$F$13*(1+$E$14*(B19-$C$13)/365),IF(B19<=$C$15,$F$14*(1+$E$15*(B19-$C$14)/365),$F$15*(1+$E$15*(B19-$C$15)/365))))))))) | E19: =(D19-1)*365/B19 | F19: =C19-E19 | G19: =(C19-E19)*10000 | J19: 1M | K19: =E19 | L19: =C19 | M19: =G19
A20: 2M | B20: =data!C21 | C20: =data!B21 | D20: =IF(B20<=$C$8,(1+$E$8*B20/365),IF(B20<=$C$9,$F$8*(1+$E$9*(B20-$C$8)/365),IF(B20<=$C$10,$F$9*(1+$E$10*(B20-$C$9)/365),IF(B20<=$C$11,$F$10*(1+$E$11*(B20-$C$10)/365),IF(B20<=$C$12,$F$11*(1+$E$12*(B20-$C$11)/365),IF(B20<=$C$13,$F$12*(1+$E$13*(B20-$C$12)/365),IF(B20<=$C$14,$F$13*(1+$E$14*(B20-$C$13)/365),IF(B20<=$C$15,$F$14*(1+$E$15*(B20-$C$14)/365),$F$15*(1+$E$15*(B20-$C$15)/365))))))))) | E20: =(D20-1)*365/B20 | F20: =C20-E20 | G20: =(C20-E20)*10000 | J20: 2M | K20: =E20 | L20: =C20 | M20: =G20
A21: 3M | B21: =data!C22 | C21: =data!B22 | D21: =IF(B21<=$C$8,(1+$E$8*B21/365),IF(B21<=$C$9,$F$8*(1+$E$9*(B21-$C$8)/365),IF(B21<=$C$10,$F$9*(1+$E$10*(B21-$C$9)/365),IF(B21<=$C$11,$F$10*(1+$E$11*(B21-$C$10)/365),IF(B21<=$C$12,$F$11*(1+$E$12*(B21-$C$11)/365),IF(B21<=$C$13,$F$12*(1+$E$13*(B21-$C$12)/365),IF(B21<=$C$14,$F$13*(1+$E$14*(B21-$C$13)/365),IF(B21<=$C$15,$F$14*(1+$E$15*(B21-$C$14)/365),$F$15*(1+$E$15*(B21-$C$15)/365))))))))) | E21: =(D21-1)*365/B21 | F21: =C21-E21 | G21: =(C21-E21)*10000 | J21: 3M | K21: =E21 | L21: =C21 | M21: =G21
A22: 4M | B22: =data!C23 | C22: =data!B23 | D22: =IF(B22<=$C$8,(1+$E$8*B22/365),IF(B22<=$C$9,$F$8*(1+$E$9*(B22-$C$8)/365),IF(B22<=$C$10,$F$9*(1+$E$10*(B22-$C$9)/365),IF(B22<=$C$11,$F$10*(1+$E$11*(B22-$C$10)/365),IF(B22<=$C$12,$F$11*(1+$E$12*(B22-$C$11)/365),IF(B22<=$C$13,$F$12*(1+$E$13*(B22-$C$12)/365),IF(B22<=$C$14,$F$13*(1+$E$14*(B22-$C$13)/365),IF(B22<=$C$15,$F$14*(1+$E$15*(B22-$C$14)/365),$F$15*(1+$E$15*(B22-$C$15)/365))))))))) | E22: =(D22-1)*365/B22 | F22: =C22-E22 | G22: =(C22-E22)*10000 | J22: 4M | K22: =E22 | L22: =C22 | M22: =G22
A23: 5M | B23: =data!C24 | C23: =data!B24 | D23: =IF(B23<=$C$8,(1+$E$8*B23/365),IF(B23<=$C$9,$F$8*(1+$E$9*(B23-$C$8)/365),IF(B23<=$C$10,$F$9*(1+$E$10*(B23-$C$9)/365),IF(B23<=$C$11,$F$10*(1+$E$11*(B23-$C$10)/365),IF(B23<=$C$12,$F$11*(1+$E$12*(B23-$C$11)/365),IF(B23<=$C$13,$F$12*(1+$E$13*(B23-$C$12)/365),IF(B23<=$C$14,$F$13*(1+$E$14*(B23-$C$13)/365),IF(B23<=$C$15,$F$14*(1+$E$15*(B23-$C$14)/365),$F$15*(1+$E$15*(B23-$C$15)/365))))))))) | E23: =(D23-1)*365/B23 | F23: =C23-E23 | G23: =(C23-E23)*10000 | J23: 5M | K23: =E23 | L23: =C23 | M23: =G23
A24: 6M | B24: =data!C25 | C24: =data!B25 | D24: =IF(B24<=$C$8,(1+$E$8*B24/365),IF(B24<=$C$9,$F$8*(1+$E$9*(B24-$C$8)/365),IF(B24<=$C$10,$F$9*(1+$E$10*(B24-$C$9)/365),IF(B24<=$C$11,$F$10*(1+$E$11*(B24-$C$10)/365),IF(B24<=$C$12,$F$11*(1+$E$12*(B24-$C$11)/365),IF(B24<=$C$13,$F$12*(1+$E$13*(B24-$C$12)/365),IF(B24<=$C$14,$F$13*(1+$E$14*(B24-$C$13)/365),IF(B24<=$C$15,$F$14*(1+$E$15*(B24-$C$14)/365),$F$15*(1+$E$15*(B24-$C$15)/365))))))))) | E24: =(D24-1)*365/B24 | F24: =C24-E24 | G24: =(C24-E24)*10000 | J24: 6M | K24: =E24 | L24: =C24 | M24: =G24
A25: 7M | B25: =data!C26 | C25: =data!B26 | D25: =IF(B25<=$C$8,(1+$E$8*B25/365),IF(B25<=$C$9,$F$8*(1+$E$9*(B25-$C$8)/365),IF(B25<=$C$10,$F$9*(1+$E$10*(B25-$C$9)/365),IF(B25<=$C$11,$F$10*(1+$E$11*(B25-$C$10)/365),IF(B25<=$C$12,$F$11*(1+$E$12*(B25-$C$11)/365),IF(B25<=$C$13,$F$12*(1+$E$13*(B25-$C$12)/365),IF(B25<=$C$14,$F$13*(1+$E$14*(B25-$C$13)/365),IF(B25<=$C$15,$F$14*(1+$E$15*(B25-$C$14)/365),$F$15*(1+$E$15*(B25-$C$15)/365))))))))) | E25: =(D25-1)*365/B25 | F25: =C25-E25 | G25: =(C25-E25)*10000 | J25: 7M | K25: =E25 | L25: =C25 | M25: =G25
A26: 8M | B26: =data!C27 | C26: =data!B27 | D26: =IF(B26<=$C$8,(1+$E$8*B26/365),IF(B26<=$C$9,$F$8*(1+$E$9*(B26-$C$8)/365),IF(B26<=$C$10,$F$9*(1+$E$10*(B26-$C$9)/365),IF(B26<=$C$11,$F$10*(1+$E$11*(B26-$C$10)/365),IF(B26<=$C$12,$F$11*(1+$E$12*(B26-$C$11)/365),IF(B26<=$C$13,$F$12*(1+$E$13*(B26-$C$12)/365),IF(B26<=$C$14,$F$13*(1+$E$14*(B26-$C$13)/365),IF(B26<=$C$15,$F$14*(1+$E$15*(B26-$C$14)/365),$F$15*(1+$E$15*(B26-$C$15)/365))))))))) | E26: =(D26-1)*365/B26 | F26: =C26-E26 | G26: =(C26-E26)*10000 | J26: 8M | K26: =E26 | L26: =C26 | M26: =G26
A27: 9M | B27: =data!C28 | C27: =data!B28 | D27: =IF(B27<=$C$8,(1+$E$8*B27/365),IF(B27<=$C$9,$F$8*(1+$E$9*(B27-$C$8)/365),IF(B27<=$C$10,$F$9*(1+$E$10*(B27-$C$9)/365),IF(B27<=$C$11,$F$10*(1+$E$11*(B27-$C$10)/365),IF(B27<=$C$12,$F$11*(1+$E$12*(B27-$C$11)/365),IF(B27<=$C$13,$F$12*(1+$E$13*(B27-$C$12)/365),IF(B27<=$C$14,$F$13*(1+$E$14*(B27-$C$13)/365),IF(B27<=$C$15,$F$14*(1+$E$15*(B27-$C$14)/365),$F$15*(1+$E$15*(B27-$C$15)/365))))))))) | E27: =(D27-1)*365/B27 | F27: =C27-E27 | G27: =(C27-E27)*10000 | J27: 9M | K27: =E27 | L27: =C27 | M27: =G27
A28: 10M | B28: =data!C29 | C28: =data!B29 | D28: =IF(B28<=$C$8,(1+$E$8*B28/365),IF(B28<=$C$9,$F$8*(1+$E$9*(B28-$C$8)/365),IF(B28<=$C$10,$F$9*(1+$E$10*(B28-$C$9)/365),IF(B28<=$C$11,$F$10*(1+$E$11*(B28-$C$10)/365),IF(B28<=$C$12,$F$11*(1+$E$12*(B28-$C$11)/365),IF(B28<=$C$13,$F$12*(1+$E$13*(B28-$C$12)/365),IF(B28<=$C$14,$F$13*(1+$E$14*(B28-$C$13)/365),IF(B28<=$C$15,$F$14*(1+$E$15*(B28-$C$14)/365),$F$15*(1+$E$15*(B28-$C$15)/365))))))))) | E28: =(D28-1)*365/B28 | F28: =C28-E28 | G28: =(C28-E28)*10000 | J28: 10M | K28: =E28 | L28: =C28 | M28: =G28
A29: 11M | B29: =data!C30 | C29: =data!B30 | D29: =IF(B29<=$C$8,(1+$E$8*B29/365),IF(B29<=$C$9,$F$8*(1+$E$9*(B29-$C$8)/365),IF(B29<=$C$10,$F$9*(1+$E$10*(B29-$C$9)/365),IF(B29<=$C$11,$F$10*(1+$E$11*(B29-$C$10)/365),IF(B29<=$C$12,$F$11*(1+$E$12*(B29-$C$11)/365),IF(B29<=$C$13,$F$12*(1+$E$13*(B29-$C$12)/365),IF(B29<=$C$14,$F$13*(1+$E$14*(B29-$C$13)/365),IF(B29<=$C$15,$F$14*(1+$E$15*(B29-$C$14)/365),$F$15*(1+$E$15*(B29-$C$15)/365))))))))) | E29: =(D29-1)*365/B29 | F29: =C29-E29 | G29: =(C29-E29)*10000 | J29: 11M | K29: =E29 | L29: =C29 | M29: =G29
A30: 12M | B30: =data!C31 | C30: =data!B31 | D30: =IF(B30<=$C$8,(1+$E$8*B30/365),IF(B30<=$C$9,$F$8*(1+$E$9*(B30-$C$8)/365),IF(B30<=$C$10,$F$9*(1+$E$10*(B30-$C$9)/365),IF(B30<=$C$11,$F$10*(1+$E$11*(B30-$C$10)/365),IF(B30<=$C$12,$F$11*(1+$E$12*(B30-$C$11)/365),IF(B30<=$C$13,$F$12*(1+$E$13*(B30-$C$12)/365),IF(B30<=$C$14,$F$13*(1+$E$14*(B30-$C$13)/365),IF(B30<=$C$15,$F$14*(1+$E$15*(B30-$C$14)/365),$F$15*(1+$E$15*(B30-$C$15)/365))))))))) | E30: =(D30-1)*365/B30 | F30: =C30-E30 | G30: =(C30-E30)*10000 | H30: ※MPM8超→外挿 | J30: 12M | K30: =E30 | L30: =C30 | M30: =G30
A31: 15M | B31: =data!C32 | C31: =data!B32 | D31: =IF(B31<=$C$8,(1+$E$8*B31/365),IF(B31<=$C$9,$F$8*(1+$E$9*(B31-$C$8)/365),IF(B31<=$C$10,$F$9*(1+$E$10*(B31-$C$9)/365),IF(B31<=$C$11,$F$10*(1+$E$11*(B31-$C$10)/365),IF(B31<=$C$12,$F$11*(1+$E$12*(B31-$C$11)/365),IF(B31<=$C$13,$F$12*(1+$E$13*(B31-$C$12)/365),IF(B31<=$C$14,$F$13*(1+$E$14*(B31-$C$13)/365),IF(B31<=$C$15,$F$14*(1+$E$15*(B31-$C$14)/365),$F$15*(1+$E$15*(B31-$C$15)/365))))))))) | E31: =(D31-1)*365/B31 | F31: =C31-E31 | G31: =(C31-E31)*10000 | H31: ※MPM8超→外挿 | J31: 15M | K31: =E31 | L31: =C31 | M31: =G31
A34: 【計算定義】 Act/365 Fixed, 単利建て（日本円OIS市場標準）
A35: ① デイカウント: ACT/365 Fixed（全期間共通）
A36: ② BOJスワップ M_i (JPBOJ1-8ONI): フォワード期間OIS金利（単利建て）
A37: JPBOJ1ONI: スポット日 → MPM1実効日 の期間フォワード金利
A38: JPBOJ2ONI: MPM1実効日 → MPM2実効日 の期間フォワード金利（以降同様）
A39: ③ 累積FV: FV_0=1, FV_i = FV_{i-1} × (1 + M_i × ΔD_i/365)
A40: ΔD_i = D(MPM_i実効日) - D(MPM_{i-1}実効日) [i=1のみ D(MPM1) - D(Spot)]
A41: ④ テナーT(実日数D_T)のFV逆算: D_{k-1} < D_T ≤ D_k の場合
A42: FV_T = FV_{k-1} × (1 + M_k × (D_T - D_{k-1})/365) ← 期間内一定ON金利を仮定
A43: ⑤ インプライドスポット金利: r_implied = (FV_T - 1) × 365/D_T [単利, ACT/365]
A44: ⑥ 歪み = 実スポット金利 − インプライドスポット金利 [bps換算: ×10000]
A45: ⑦ MPM8超テナー(15M等): M8フォワード金利で外挿（ON金利一定継続の仮定）
...

Sheet スポット→BOJ
A1: スポット OIS → BOJ グリッドレート 逆算（ブートストラップ）
A2: 【手法】市場スポット OIS（1M〜15M）を MPM 発効日で区分線形補間 → 8 点でブートストラップ → グリッドレート Mn 逆算。STEP 3 の残差で補間精度を確認。
A4: STEP 1/2: MPM発効日でのスポット補間 → グリッドレート逆算（ACT/365 Fixed）
A5: 会合 | B5: MPM発効日 | C5: 実日数 (Dk) | D5: 補間スポットOIS (Step1) | E5: 累積複利係数 (Step2) | F5: 期間複利係数 (Step2) | G5: 逆算Mn (Step2) | H5: 開始日数 (H:helper) | I5: 期間日数 (I:helper) | J5: 補間区間 (参考)
A6: M1 | B6: =data!$C$9 | C6: =data!$D$9 | D6: =LET(xs,data!$C$20:$C$32,ys,data!$B$20:$B$32,n,13,Dk,C6,idx,MAX(1,MIN(n-1,IF(Dk>=INDEX(xs,n),n-1,MATCH(Dk,xs,1)))),ylo,INDEX(ys,idx),yhi,INDEX(ys,idx+1),xlo,INDEX(xs,idx),xhi,INDEX(xs,idx+1),IF(xhi=xlo,ylo,ylo+(yhi-ylo)*(Dk-xlo)/(xhi-xlo))) | E6: =1+D6*C6/365 | F6: =E6 | G6: =(F6-1)/(C6/365) | H6: =0 | I6: =C6-H6 | J6: =LET(xs,data!$C$20:$C$32,ys,data!$D$20:$D$32,n,13,Dk,C6,idx,MAX(1,MIN(n-1,IF(Dk>=INDEX(xs,n),n-1,MATCH(Dk,xs,1)))),INDEX(ys,idx)&"("&INDEX(xs,idx)&"d) ～ "&INDEX(ys,idx+1)&"("&INDEX(xs,idx+1)&"d)")
A7: M2 | B7: =data!$C$10 | C7: =data!$D$10 | D7: =LET(xs,data!$C$20:$C$32,ys,data!$B$20:$B$32,n,13,Dk,C7,idx,MAX(1,MIN(n-1,IF(Dk>=INDEX(xs,n),n-1,MATCH(Dk,xs,1)))),ylo,INDEX(ys,idx),yhi,INDEX(ys,idx+1),xlo,INDEX(xs,idx),xhi,INDEX(xs,idx+1),IF(xhi=xlo,ylo,ylo+(yhi-ylo)*(Dk-xlo)/(xhi-xlo))) | E7: =1+D7*C7/365 | F7: =E7/E6 | G7: =(F7-1)/((C7-C6)/365) | H7: =C6 | I7: =C7-H7 | J7: =LET(xs,data!$C$20:$C$32,ys,data!$D$20:$D$32,n,13,Dk,C7,idx,MAX(1,MIN(n-1,IF(Dk>=INDEX(xs,n),n-1,MATCH(Dk,xs,1)))),INDEX(ys,idx)&"("&INDEX(xs,idx)&"d) ～ "&INDEX(ys,idx+1)&"("&INDEX(xs,idx+1)&"d)")
A8: M3 | B8: =data!$C$11 | C8: =data!$D$11 | D8: =LET(xs,data!$C$20:$C$32,ys,data!$B$20:$B$32,n,13,Dk,C8,idx,MAX(1,MIN(n-1,IF(Dk>=INDEX(xs,n),n-1,MATCH(Dk,xs,1)))),ylo,INDEX(ys,idx),yhi,INDEX(ys,idx+1),xlo,INDEX(xs,idx),xhi,INDEX(xs,idx+1),IF(xhi=xlo,ylo,ylo+(yhi-ylo)*(Dk-xlo)/(xhi-xlo))) | E8: =1+D8*C8/365 | F8: =E8/E7 | G8: =(F8-1)/((C8-C7)/365) | H8: =C7 | I8: =C8-H8 | J8: =LET(xs,data!$C$20:$C$32,ys,data!$D$20:$D$32,n,13,Dk,C8,idx,MAX(1,MIN(n-1,IF(Dk>=INDEX(xs,n),n-1,MATCH(Dk,xs,1)))),INDEX(ys,idx)&"("&INDEX(xs,idx)&"d) ～ "&INDEX(ys,idx+1)&"("&INDEX(xs,idx+1)&"d)")
A9: M4 | B9: =data!$C$12 | C9: =data!$D$12 | D9: =LET(xs,data!$C$20:$C$32,ys,data!$B$20:$B$32,n,13,Dk,C9,idx,MAX(1,MIN(n-1,IF(Dk>=INDEX(xs,n),n-1,MATCH(Dk,xs,1)))),ylo,INDEX(ys,idx),yhi,INDEX(ys,idx+1),xlo,INDEX(xs,idx),xhi,INDEX(xs,idx+1),IF(xhi=xlo,ylo,ylo+(yhi-ylo)*(Dk-xlo)/(xhi-xlo))) | E9: =1+D9*C9/365 | F9: =E9/E8 | G9: =(F9-1)/((C9-C8)/365) | H9: =C8 | I9: =C9-H9 | J9: =LET(xs,data!$C$20:$C$32,ys,data!$D$20:$D$32,n,13,Dk,C9,idx,MAX(1,MIN(n-1,IF(Dk>=INDEX(xs,n),n-1,MATCH(Dk,xs,1)))),INDEX(ys,idx)&"("&INDEX(xs,idx)&"d) ～ "&INDEX(ys,idx+1)&"("&INDEX(xs,idx+1)&"d)")
A10: M5 | B10: =data!$C$13 | C10: =data!$D$13 | D10: =LET(xs,data!$C$20:$C$32,ys,data!$B$20:$B$32,n,13,Dk,C10,idx,MAX(1,MIN(n-1,IF(Dk>=INDEX(xs,n),n-1,MATCH(Dk,xs,1)))),ylo,INDEX(ys,idx),yhi,INDEX(ys,idx+1),xlo,INDEX(xs,idx),xhi,INDEX(xs,idx+1),IF(xhi=xlo,ylo,ylo+(yhi-ylo)*(Dk-xlo)/(xhi-xlo))) | E10: =1+D10*C10/365 | F10: =E10/E9 | G10: =(F10-1)/((C10-C9)/365) | H10: =C9 | I10: =C10-H10 | J10: =LET(xs,data!$C$20:$C$32,ys,data!$D$20:$D$32,n,13,Dk,C10,idx,MAX(1,MIN(n-1,IF(Dk>=INDEX(xs,n),n-1,MATCH(Dk,xs,1)))),INDEX(ys,idx)&"("&INDEX(xs,idx)&"d) ～ "&INDEX(ys,idx+1)&"("&INDEX(xs,idx+1)&"d)")
A11: M6 | B11: =data!$C$14 | C11: =data!$D$14 | D11: =LET(xs,data!$C$20:$C$32,ys,data!$B$20:$B$32,n,13,Dk,C11,idx,MAX(1,MIN(n-1,IF(Dk>=INDEX(xs,n),n-1,MATCH(Dk,xs,1)))),ylo,INDEX(ys,idx),yhi,INDEX(ys,idx+1),xlo,INDEX(xs,idx),xhi,INDEX(xs,idx+1),IF(xhi=xlo,ylo,ylo+(yhi-ylo)*(Dk-xlo)/(xhi-xlo))) | E11: =1+D11*C11/365 | F11: =E11/E10 | G11: =(F11-1)/((C11-C10)/365) | H11: =C10 | I11: =C11-H11 | J11: =LET(xs,data!$C$20:$C$32,ys,data!$D$20:$D$32,n,13,Dk,C11,idx,MAX(1,MIN(n-1,IF(Dk>=INDEX(xs,n),n-1,MATCH(Dk,xs,1)))),INDEX(ys,idx)&"("&INDEX(xs,idx)&"d) ～ "&INDEX(ys,idx+1)&"("&INDEX(xs,idx+1)&"d)")
A12: M7 | B12: =data!$C$15 | C12: =data!$D$15 | D12: =LET(xs,data!$C$20:$C$32,ys,data!$B$20:$B$32,n,13,Dk,C12,idx,MAX(1,MIN(n-1,IF(Dk>=INDEX(xs,n),n-1,MATCH(Dk,xs,1)))),ylo,INDEX(ys,idx),yhi,INDEX(ys,idx+1),xlo,INDEX(xs,idx),xhi,INDEX(xs,idx+1),IF(xhi=xlo,ylo,ylo+(yhi-ylo)*(Dk-xlo)/(xhi-xlo))) | E12: =1+D12*C12/365 | F12: =E12/E11 | G12: =(F12-1)/((C12-C11)/365) | H12: =C11 | I12: =C12-H12 | J12: =LET(xs,data!$C$20:$C$32,ys,data!$D$20:$D$32,n,13,Dk,C12,idx,MAX(1,MIN(n-1,IF(Dk>=INDEX(xs,n),n-1,MATCH(Dk,xs,1)))),INDEX(ys,idx)&"("&INDEX(xs,idx)&"d) ～ "&INDEX(ys,idx+1)&"("&INDEX(xs,idx+1)&"d)")
A13: M8 | B13: =data!$C$16 | C13: =data!$D$16 | D13: =LET(xs,data!$C$20:$C$32,ys,data!$B$20:$B$32,n,13,Dk,C13,idx,MAX(1,MIN(n-1,IF(Dk>=INDEX(xs,n),n-1,MATCH(Dk,xs,1)))),ylo,INDEX(ys,idx),yhi,INDEX(ys,idx+1),xlo,INDEX(xs,idx),xhi,INDEX(xs,idx+1),IF(xhi=xlo,ylo,ylo+(yhi-ylo)*(Dk-xlo)/(xhi-xlo))) | E13: =1+D13*C13/365 | F13: =E13/E12 | G13: =(F13-1)/((C13-C12)/365) | H13: =C12 | I13: =C13-H13 | J13: =LET(xs,data!$C$20:$C$32,ys,data!$D$20:$D$32,n,13,Dk,C13,idx,MAX(1,MIN(n-1,IF(Dk>=INDEX(xs,n),n-1,MATCH(Dk,xs,1)))),INDEX(ys,idx)&"("&INDEX(xs,idx)&"d) ～ "&INDEX(ys,idx+1)&"("&INDEX(xs,idx+1)&"d)")
A14: M8以降 (flat) | G14: =G13 | H14: =C13 | I14: =3650 | J14: ← M8 グリッドレートを flat 延長（12M・15M 残差検証用）
A16: STEP 3: 残差検証 ─ 逆算グリッド → 再現スポット vs 市場スポット（補間精度・歪み確認）
A17: テナー | B17: 実日数 | C17: 市場スポット | D17: 再現スポット (逆算グリッドから) | E17: 残差 実際－再現 (bp) | F17: 累積残差 (bp) | G17: 備考
A18: 1M | B18: =data!$C$20 | C18: =data!$B$20 | D18: =(EXP(SUMPRODUCT(LN(1+$G$6:$G$14*MIN(MAX(B18-$H$6:$H$14,0),$I$6:$I$14)/365)))-1)/(B18/365) | E18: =(C18-D18)*10000 | F18: =E18
A19: 2M | B19: =data!$C$21 | C19: =data!$B$21 | D19: =(EXP(SUMPRODUCT(LN(1+$G$6:$G$14*MIN(MAX(B19-$H$6:$H$14,0),$I$6:$I$14)/365)))-1)/(B19/365) | E19: =(C19-D19)*10000 | F19: =F18+E19
A20: 3M | B20: =data!$C$22 | C20: =data!$B$22 | D20: =(EXP(SUMPRODUCT(LN(1+$G$6:$G$14*MIN(MAX(B20-$H$6:$H$14,0),$I$6:$I$14)/365)))-1)/(B20/365) | E20: =(C20-D20)*10000 | F20: =F19+E20
A21: 4M | B21: =data!$C$23 | C21: =data!$B$23 | D21: =(EXP(SUMPRODUCT(LN(1+$G$6:$G$14*MIN(MAX(B21-$H$6:$H$14,0),$I$6:$I$14)/365)))-1)/(B21/365) | E21: =(C21-D21)*10000 | F21: =F20+E21
A22: 5M | B22: =data!$C$24 | C22: =data!$B$24 | D22: =(EXP(SUMPRODUCT(LN(1+$G$6:$G$14*MIN(MAX(B22-$H$6:$H$14,0),$I$6:$I$14)/365)))-1)/(B22/365) | E22: =(C22-D22)*10000 | F22: =F21+E22
A23: 6M | B23: =data!$C$25 | C23: =data!$B$25 | D23: =(EXP(SUMPRODUCT(LN(1+$G$6:$G$14*MIN(MAX(B23-$H$6:$H$14,0),$I$6:$I$14)/365)))-1)/(B23/365) | E23: =(C23-D23)*10000 | F23: =F22+E23
A24: 7M | B24: =data!$C$26 | C24: =data!$B$26 | D24: =(EXP(SUMPRODUCT(LN(1+$G$6:$G$14*MIN(MAX(B24-$H$6:$H$14,0),$I$6:$I$14)/365)))-1)/(B24/365) | E24: =(C24-D24)*10000 | F24: =F23+E24
A25: 8M | B25: =data!$C$27 | C25: =data!$B$27 | D25: =(EXP(SUMPRODUCT(LN(1+$G$6:$G$14*MIN(MAX(B25-$H$6:$H$14,0),$I$6:$I$14)/365)))-1)/(B25/365) | E25: =(C25-D25)*10000 | F25: =F24+E25
A26: 9M | B26: =data!$C$28 | C26: =data!$B$28 | D26: =(EXP(SUMPRODUCT(LN(1+$G$6:$G$14*MIN(MAX(B26-$H$6:$H$14,0),$I$6:$I$14)/365)))-1)/(B26/365) | E26: =(C26-D26)*10000 | F26: =F25+E26
A27: 10M | B27: =data!$C$29 | C27: =data!$B$29 | D27: =(EXP(SUMPRODUCT(LN(1+$G$6:$G$14*MIN(MAX(B27-$H$6:$H$14,0),$I$6:$I$14)/365)))-1)/(B27/365) | E27: =(C27-D27)*10000 | F27: =F26+E27
A28: 11M | B28: =data!$C$30 | C28: =data!$B$30 | D28: =(EXP(SUMPRODUCT(LN(1+$G$6:$G$14*MIN(MAX(B28-$H$6:$H$14,0),$I$6:$I$14)/365)))-1)/(B28/365) | E28: =(C28-D28)*10000 | F28: =F27+E28
A29: 12M | B29: =data!$C$31 | C29: =data!$B$31 | D29: =(EXP(SUMPRODUCT(LN(1+$G$6:$G$14*MIN(MAX(B29-$H$6:$H$14,0),$I$6:$I$14)/365)))-1)/(B29/365) | E29: =(C29-D29)*10000 | F29: =F28+E29 | G29: M8超→flat延長
A30: 15M | B30: =data!$C$32 | C30: =data!$B$32 | D30: =(EXP(SUMPRODUCT(LN(1+$G$6:$G$14*MIN(MAX(B30-$H$6:$H$14,0),$I$6:$I$14)/365)))-1)/(B30/365) | E30: =(C30-D30)*10000 | F30: =F29+E30 | G30: M8超→flat延長
A32: 【解釈】 残差 ≈ 0 → 市場スポットと BOJ グリッドの整合性が高い
A33: 残差が大きいテナー = 市場スポット曲線と BOJ 価格の乖離（歪み）
A34: 12M・15M は M8 発効日（約 358 日）を超えるため flat 延長で近似（誤差大きめ）
A35: 【注意】 LET 関数は Excel 365 / Excel 2021 以降が必要です

Sheet 利上げパス
A1: 利上げパス → 理論 BOJ グリッドレート・スポット OIS 曲線（2Y まで）
A2: 【使い方】 D5 に現在政策金利を入力。C7:C14（黄色セル）に各会合の利上げ幅（bp）を入力。0 = 据え置き、25 = 25bp 利上げ、-10 = 10bp 引下げ。
A4: 入力: 現在政策金利・各会合の利上げ幅
A5: 会合 | B5: MPM発効日 | C5: 利上げ幅(bp) ★ここを入力★ | D5: 期間中 政策金利
A6: 現在 | B6: =data!$B$5 | C6: ─ | D6: 0.00495
A7: M1 | B7: =data!$C$9 | C7: 0 | D7: =D6
A8: M2 | B8: =data!$C$10 | C8: 0 | D8: =D7+C7/10000
A9: M3 | B9: =data!$C$11 | C9: 0 | D9: =D8+C8/10000
A10: M4 | B10: =data!$C$12 | C10: 0 | D10: =D9+C9/10000
A11: M5 | B11: =data!$C$13 | C11: 0 | D11: =D10+C10/10000
A12: M6 | B12: =data!$C$14 | C12: 0 | D12: =D11+C11/10000
A13: M7 | B13: =data!$C$15 | C13: 0 | D13: =D12+C12/10000
A14: M8 | B14: =data!$C$16 | C14: 0 | D14: =D13+C13/10000
A15: M8後 | D15: =D14+C14/10000 | E15: ← M8 会合後の最終政策金利
A17: 理論グリッドレート・複利計算テーブル（ACT/365 Fixed）
A18: 会合 | B18: 期間開始 日数 | C18: 期間終了 日数 | D18: 期間 日数 | E18: グリッドレート (期間中政策金利) | F18: 期間複利係数 | G18: 累積複利係数 | H18: 理論スポット OIS | I18: 備考
A19: M1 | B19: =0 | C19: =data!$D$9 | D19: =C19-B19 | E19: =$D$7 | F19: =1+E19*D19/365 | G19: =F19 | H19: =(G19-1)/(C19/365)
A20: M2 | B20: =C19 | C20: =data!$D$10 | D20: =C20-B20 | E20: =$D$8 | F20: =1+E20*D20/365 | G20: =G19*F20 | H20: =(G20-1)/(C20/365)
A21: M3 | B21: =C20 | C21: =data!$D$11 | D21: =C21-B21 | E21: =$D$9 | F21: =1+E21*D21/365 | G21: =G20*F21 | H21: =(G21-1)/(C21/365)
A22: M4 | B22: =C21 | C22: =data!$D$12 | D22: =C22-B22 | E22: =$D$10 | F22: =1+E22*D22/365 | G22: =G21*F22 | H22: =(G22-1)/(C22/365)
A23: M5 | B23: =C22 | C23: =data!$D$13 | D23: =C23-B23 | E23: =$D$11 | F23: =1+E23*D23/365 | G23: =G22*F23 | H23: =(G23-1)/(C23/365)
A24: M6 | B24: =C23 | C24: =data!$D$14 | D24: =C24-B24 | E24: =$D$12 | F24: =1+E24*D24/365 | G24: =G23*F24 | H24: =(G24-1)/(C24/365)
A25: M7 | B25: =C24 | C25: =data!$D$15 | D25: =C25-B25 | E25: =$D$13 | F25: =1+E25*D25/365 | G25: =G24*F25 | H25: =(G25-1)/(C25/365)
A26: M8 | B26: =C25 | C26: =data!$D$16 | D26: =C26-B26 | E26: =$D$14 | F26: =1+E26*D26/365 | G26: =G25*F26 | H26: =(G26-1)/(C26/365)
A27: M8以降 (flat) | B27: =C26 | C27: =C26+3650 | D27: =3650 | E27: =$D$15 | F27: =1+E27*D27/365 | I27: ← 2Y（730d）等の長テナー計算用 flat 延長ダミー
A29: 理論スポット OIS 曲線（1M〜2Y）vs 市場スポット OIS
A30: テナー | B30: 実日数 (概算) | C30: 理論スポット OIS | D30: 市場スポット OIS (参考: data シート) | E30: 差分 理論－市場 (bp)
A31: 1M | B31: =EDATE(data!$B$5,1)-data!$B$5 | C31: =(EXP(SUMPRODUCT(LN(1+$E$19:$E$27*MIN(MAX(B31-$B$19:$B$27,0),$D$19:$D$27)/365)))-1)/(B31/365) | D31: =data!$B$20 | E31: =(C31-D31)*10000
A32: 2M | B32: =EDATE(data!$B$5,2)-data!$B$5 | C32: =(EXP(SUMPRODUCT(LN(1+$E$19:$E$27*MIN(MAX(B32-$B$19:$B$27,0),$D$19:$D$27)/365)))-1)/(B32/365) | D32: =data!$B$21 | E32: =(C32-D32)*10000
A33: 3M | B33: =EDATE(data!$B$5,3)-data!$B$5 | C33: =(EXP(SUMPRODUCT(LN(1+$E$19:$E$27*MIN(MAX(B33-$B$19:$B$27,0),$D$19:$D$27)/365)))-1)/(B33/365) | D33: =data!$B$22 | E33: =(C33-D33)*10000
A34: 4M | B34: =EDATE(data!$B$5,4)-data!$B$5 | C34: =(EXP(SUMPRODUCT(LN(1+$E$19:$E$27*MIN(MAX(B34-$B$19:$B$27,0),$D$19:$D$27)/365)))-1)/(B34/365) | D34: =data!$B$23 | E34: =(C34-D34)*10000
A35: 5M | B35: =EDATE(data!$B$5,5)-data!$B$5 | C35: =(EXP(SUMPRODUCT(LN(1+$E$19:$E$27*MIN(MAX(B35-$B$19:$B$27,0),$D$19:$D$27)/365)))-1)/(B35/365) | D35: =data!$B$24 | E35: =(C35-D35)*10000
A36: 6M | B36: =EDATE(data!$B$5,6)-data!$B$5 | C36: =(EXP(SUMPRODUCT(LN(1+$E$19:$E$27*MIN(MAX(B36-$B$19:$B$27,0),$D$19:$D$27)/365)))-1)/(B36/365) | D36: =data!$B$25 | E36: =(C36-D36)*10000
A37: 7M | B37: =EDATE(data!$B$5,7)-data!$B$5 | C37: =(EXP(SUMPRODUCT(LN(1+$E$19:$E$27*MIN(MAX(B37-$B$19:$B$27,0),$D$19:$D$27)/365)))-1)/(B37/365) | D37: =data!$B$26 | E37: =(C37-D37)*10000
A38: 8M | B38: =EDATE(data!$B$5,8)-data!$B$5 | C38: =(EXP(SUMPRODUCT(LN(1+$E$19:$E$27*MIN(MAX(B38-$B$19:$B$27,0),$D$19:$D$27)/365)))-1)/(B38/365) | D38: =data!$B$27 | E38: =(C38-D38)*10000
A39: 9M | B39: =EDATE(data!$B$5,9)-data!$B$5 | C39: =(EXP(SUMPRODUCT(LN(1+$E$19:$E$27*MIN(MAX(B39-$B$19:$B$27,0),$D$19:$D$27)/365)))-1)/(B39/365) | D39: =data!$B$28 | E39: =(C39-D39)*10000
A40: 10M | B40: =EDATE(data!$B$5,10)-data!$B$5 | C40: =(EXP(SUMPRODUCT(LN(1+$E$19:$E$27*MIN(MAX(B40-$B$19:$B$27,0),$D$19:$D$27)/365)))-1)/(B40/365) | D40: =data!$B$29 | E40: =(C40-D40)*10000
A41: 11M | B41: =EDATE(data!$B$5,11)-data!$B$5 | C41: =(EXP(SUMPRODUCT(LN(1+$E$19:$E$27*MIN(MAX(B41-$B$19:$B$27,0),$D$19:$D$27)/365)))-1)/(B41/365) | D41: =data!$B$30 | E41: =(C41-D41)*10000
A42: 12M | B42: =EDATE(data!$B$5,12)-data!$B$5 | C42: =(EXP(SUMPRODUCT(LN(1+$E$19:$E$27*MIN(MAX(B42-$B$19:$B$27,0),$D$19:$D$27)/365)))-1)/(B42/365) | D42: =data!$B$31 | E42: =(C42-D42)*10000
A43: 15M | B43: =EDATE(data!$B$5,15)-data!$B$5 | C43: =(EXP(SUMPRODUCT(LN(1+$E$19:$E$27*MIN(MAX(B43-$B$19:$B$27,0),$D$19:$D$27)/365)))-1)/(B43/365) | D43: =data!$B$32 | E43: =(C43-D43)*10000
...
